Workbook

Sheet Сводка
B2: Сравнительная аналитика счетов
B3: Отопление / тёплый пол · дата документов 07.09.2026 · покупатель КФХ Галимова Р.М. (в счёте КЛ-1864)
B5: СЧЁТ КЛ-1864 | F5: НАКЛАДНАЯ МС | J5: МС ДОРОЖЕ НА
B6: 461511.57 | F6: 599564 | J6: 138052.43
B7: ИП Абдулрашитов Р.В. · 44 наим. · в т.ч. НДС 22% 83 223,40 ₽ | F7: ИП Баширова С.М. · тов. чек 00УТ-015924 · 47 строк / 41 позиция | J7: относительно КЛ-1864 · +29,9% | КЛ дешевле МС на 23,0%
B9: На что обратить внимание
B10: Не эквивалент | F10: Не хватает в МС | J10: Замены бренда
B11: Радиатор 6 секц. Revolution в КЛ заменён на 10 секц. MONOBLOCK в МС. Кран 1″ прямой VT.227S.N.06 заменён на угловой VT.228.N.06. | F11: Пресс 26×1″: в КЛ 10 шт, в МС 8 шт (−2). Пресс 26×3/4″: в КЛ 6 шт, в МС 5 шт (−1). Остальной состав совпадает по количеству. | J11: Коллекторы ONDO→ТМ, клапан VALTEC→ZEGOR, насос ГВС Vieir→Unipump, гидрострелка Север→Дельта, краны VIEIR→STI.
B14: Разница по группам товаров
B15: Группа | C15: Сумма КЛ, ₽ | D15: Сумма МС, ₽ | E15: Δ, ₽ | F15: МС дороже, % | G15: Вклад в разницу
B16: Радиаторы | C16: =SUMIF('Сравнение позиций'!$B$6:$B$46,B16,'Сравнение позиций'!$G$6:$G$46) | D16: =SUMIF('Сравнение позиций'!$B$6:$B$46,B16,'Сравнение позиций'!$L$6:$L$46) | E16: =D16-C16 | F16: =IF(C16=0,"",D16/C16-1) | G16: =IF(SUM($E$16:$E$22)=0,"",E16/SUM($E$16:$E$22))
B17: Обвязка радиаторов | C17: =SUMIF('Сравнение позиций'!$B$6:$B$46,B17,'Сравнение позиций'!$G$6:$G$46) | D17: =SUMIF('Сравнение позиций'!$B$6:$B$46,B17,'Сравнение позиций'!$L$6:$L$46) | E17: =D17-C17 | F17: =IF(C17=0,"",D17/C17-1) | G17: =IF(SUM($E$16:$E$22)=0,"",E17/SUM($E$16:$E$22))
B18: Пресс-фитинги VALTEC | C18: =SUMIF('Сравнение позиций'!$B$6:$B$46,B18,'Сравнение позиций'!$G$6:$G$46) | D18: =SUMIF('Сравнение позиций'!$B$6:$B$46,B18,'Сравнение позиций'!$L$6:$L$46) | E18: =D18-C18 | F18: =IF(C18=0,"",D18/C18-1) | G18: =IF(SUM($E$16:$E$22)=0,"",E18/SUM($E$16:$E$22))
B19: Трубы и изоляция | C19: =SUMIF('Сравнение позиций'!$B$6:$B$46,B19,'Сравнение позиций'!$G$6:$G$46) | D19: =SUMIF('Сравнение позиций'!$B$6:$B$46,B19,'Сравнение позиций'!$L$6:$L$46) | E19: =D19-C19 | F19: =IF(C19=0,"",D19/C19-1) | G19: =IF(SUM($E$16:$E$22)=0,"",E19/SUM($E$16:$E$22))
B20: Коллекторы тёплого пола | C20: =SUMIF('Сравнение позиций'!$B$6:$B$46,B20,'Сравнение позиций'!$G$6:$G$46) | D20: =SUMIF('Сравнение позиций'!$B$6:$B$46,B20,'Сравнение позиций'!$L$6:$L$46) | E20: =D20-C20 | F20: =IF(C20=0,"",D20/C20-1) | G20: =IF(SUM($E$16:$E$22)=0,"",E20/SUM($E$16:$E$22))
B21: Смесители и насосы | C21: =SUMIF('Сравнение позиций'!$B$6:$B$46,B21,'Сравнение позиций'!$G$6:$G$46) | D21: =SUMIF('Сравнение позиций'!$B$6:$B$46,B21,'Сравнение позиций'!$L$6:$L$46) | E21: =D21-C21 | F21: =IF(C21=0,"",D21/C21-1) | G21: =IF(SUM($E$16:$E$22)=0,"",E21/SUM($E$16:$E$22))
B22: Краны и арматура | C22: =SUMIF('Сравнение позиций'!$B$6:$B$46,B22,'Сравнение позиций'!$G$6:$G$46) | D22: =SUMIF('Сравнение позиций'!$B$6:$B$46,B22,'Сравнение позиций'!$L$6:$L$46) | E22: =D22-C22 | F22: =IF(C22=0,"",D22/C22-1) | G22: =IF(SUM($E$16:$E$22)=0,"",E22/SUM($E$16:$E$22))
B23: ИТОГО | C23: =SUM(C16:C22) | D23: =SUM(D16:D22) | E23: =D23-C23 | F23: =D23/C23-1 | G23: 1
B25: Одинаковый товар vs замены
B26: Категория сопоставления | C26: Сумма КЛ, ₽ | D26: Сумма МС, ₽ | E26: Δ, ₽ | F26: МС дороже, % | G26: Позиций
B27: Одинаковый артикул / товар | C27: =SUMIF('Сравнение позиций'!$P$6:$P$46,"Одинаковый артикул",'Сравнение позиций'!$G$6:$G$46)+SUMIF('Сравнение позиций'!$P$6:$P$46,"Одинаковый товар",'Сравнение позиций'!$G$6:$G$46) | D27: =SUMIF('Сравнение позиций'!$P$6:$P$46,"Одинаковый артикул",'Сравнение позиций'!$L$6:$L$46)+SUMIF('Сравнение позиций'!$P$6:$P$46,"Одинаковый товар",'Сравнение позиций'!$L$6:$L$46) | E27: =D27-C27 | F27: =D27/C27-1 | G27: =COUNTIF('Сравнение позиций'!$P$6:$P$46,"Одинаковый артикул")+COUNTIF('Сравнение позиций'!$P$6:$P$46,"Одинаковый товар")
B28: Аналоги (другой бренд / серия) | C28: =SUMIF('Сравнение позиций'!$P$6:$P$46,"Аналог",'Сравнение позиций'!$G$6:$G$46) | D28: =SUMIF('Сравнение позиций'!$P$6:$P$46,"Аналог",'Сравнение позиций'!$L$6:$L$46) | E28: =D28-C28 | F28: =D28/C28-1 | G28: =COUNTIF('Сравнение позиций'!$P$6:$P$46,"Аналог")
B29: Не эквивалент (разный товар) | C29: =SUMIF('Сравнение позиций'!$P$6:$P$46,"Не эквивалент",'Сравнение позиций'!$G$6:$G$46) | D29: =SUMIF('Сравнение позиций'!$P$6:$P$46,"Не эквивалент",'Сравнение позиций'!$L$6:$L$46) | E29: =D29-C29 | F29: =D29/C29-1 | G29: =COUNTIF('Сравнение позиций'!$P$6:$P$46,"Не эквивалент")
B32: Топ удорожаний МС · вклад в разницу счетов | J32: Где дороже КЛ-1864 (редко)
B33: Позиция | C33: Δ сумма, ₽ | D33: МС дороже, % | E33: Тип | F33: Почему так | J33: Позиция | M33: КЛ дороже
B34: Труба м/п Valtec 16×2, 1400 м | C34: 39732 | D34: 0.282 | E34: Одинаковый артикул | F34: Одинаковый VALTEC, наценка МС ~28% | J34: Клапан ручной 1/2″ VALTEC vs ZEGOR | M34: +11,4%
B35: Радиатор 6 секц. → 10 секц. MONOBLOCK | C35: 32135 | D35: 0.974 | E35: Не эквивалент | F35: Другой товар: больше секций | J35: Заглушка 1/2″ нар. VALTEC vs VRT | M35: +24,3%
B36: Смесительный узел VT.COMBI.0.180 ×2 | C36: 18312 | D36: 0.333 | E36: Одинаковый артикул | F36: Одинаковый узел, МС +33% | J36: Гидрострелка Север vs Дельта | M36: +3,8%
B37: Насос ГВС Vieir → Unipump LPA | C37: 6665 | D37: 1.46 | E37: Аналог | F37: Другая модель и монтажная длина | J37: Коллектор 5 вых. ONDO vs ТМ | M37: +3,3%
B38: Радиатор 8 секц. Revolution → MONOBLOCK | C38: 5594 | D38: 0.127 | E38: Аналог | F38: Другая серия Royal Thermo | J38: Заглушка 1″ вн. VALTEC vs VRT | M38: +4,9%
B39: Радиатор 12 секц. Revolution → MONOBLOCK | C39: 4199 | D39: 0.127 | E39: Аналог | F39: Другая серия Royal Thermo
B40: Труба м/п Valtec 20×2, 100 м | C40: 3762 | D40: 0.282 | E40: Одинаковый товар | F40: Одинаковый VALTEC, наценка ~28%
B41: Насос VALTEC RS 25/6-180 ×4 | C41: 3758 | D41: 0.282 | E41: Одинаковый артикул | F41: Одинаковый VALTEC, наценка ~28%
B42: Труба м/п Valtec 26×3, 50 м | C42: 3421 | D42: 0.282 | E42: Одинаковый товар | F42: Одинаковый VALTEC, наценка ~28%
B43: Пресс-уголок 26×26 ×17 | C43: 2872 | D43: 0.282 | E43: Одинаковый артикул | F43: Одинаковый VALTEC, наценка ~28%
B45: Методика. Позиции сопоставлены по артикулу VALTEC, затем по назначению (аналоги). Одинаковые позиции, разбитые в МС на несколько строк (насосы, пресс 26×1, уголок 26), сложены. Δ цена ед. = цена МС / цена КЛ − 1. Итоги документов: КЛ-1864 = 461 511,57 ₽ с НДС 22%; МС = 599 564 ₽. Сумма строк сравнения может отличаться от итога документа на 1–2 ₽ из-за округления цена × кол-во. В счёте КЛ-1864 НДС выделен отдельно (в т.ч.); в товарном чеке МС НДС не выделен — сравниваются цены «как в документе».
B48: Листы: Сводка → Сравнение позиций (фильтры) → Замены и аналоги → Не хватает и несовпадения

Sheet Сравнение позиций
A1: Сравнение позиций · счёт КЛ-1864 vs накладная МС
A2: Фильтр по группе / типу сопоставления включён в шапке. Красный % — МС дороже, зелёный — КЛ дороже. Жёлтый тип — аналог, красный — не эквивалент. Суммы = цена × количество (формулы, можно править цены).
C3: КЛ-1864 · ИП Абдулрашитов Р.В. · 07.09.2026 | H3: МС · ИП Баширова С.М. · расходная накладная 00УТ-015924 · 07.09.2026 | M3: Сравнение
A5: № | B5: Группа | C5: Наименование КЛ-1864 | D5: Артикул КЛ | E5: Кол-во | F5: Цена, ₽ | G5: Сумма, ₽ | H5: Наименование МС | I5: Артикул МС | J5: Кол-во | K5: Цена, ₽ | L5: Сумма, ₽ | M5: Δ цена ед. | N5: Кто дороже | O5: Δ сумма, ₽ | P5: Тип сопоставления | Q5: Δ кол-во | R5: Комментарий
A6: 1 | B6: Радиаторы | C6: Радиатор алюм. Royal Thermo Revolution 500, 8 секц. | D6: — | E6: 6 | F6: 7333.6 | G6: =E6*F6 | H6: Радиатор алюм. Royal Thermo MONOBLOCK A 500×80, 8 секц. | I6: 542451 | J6: 6 | K6: 8266 | L6: =J6*K6 | M6: =IF(F6=0,"",K6/F6-1) | N6: =IF(ABS(K6-F6)<0.005,"равно",IF(K6>F6,"МС дороже","КЛ дороже")) | O6: =L6-G6 | P6: Аналог | Q6: =J6-E6 | R6: Другая серия: Revolution vs MONOBLOCK A
A7: 2 | B7: Радиаторы | C7: Радиатор алюм. Royal Thermo Revolution 500, 6 секц. | D7: — | E7: 6 | F7: 5500.2 | G7: =E7*F7 | H7: Радиатор алюм. Royal Thermo MONOBLOCK A 500×80, 10 секц. | I7: 542452 | J7: 6 | K7: 10856 | L7: =J7*K7 | M7: =IF(F7=0,"",K7/F7-1) | N7: =IF(ABS(K7-F7)<0.005,"равно",IF(K7>F7,"МС дороже","КЛ дороже")) | O7: =L7-G7 | P7: Не эквивалент | Q7: =J7-E7 | R7: КРИТИЧНО: 6 секций vs 10 секций + другая серия
A8: 3 | B8: Радиаторы | C8: Радиатор алюм. Royal Thermo Revolution 500, 12 секц. | D8: — | E8: 3 | F8: 11000.4 | G8: =E8*F8 | H8: Радиатор алюм. Royal Thermo MONOBLOCK A 500×80, 12 секц. | I8: 542453 | J8: 3 | K8: 12400 | L8: =J8*K8 | M8: =IF(F8=0,"",K8/F8-1) | N8: =IF(ABS(K8-F8)<0.005,"равно",IF(K8>F8,"МС дороже","КЛ дороже")) | O8: =L8-G8 | P8: Аналог | Q8: =J8-E8 | R8: Другая серия: Revolution vs MONOBLOCK A
A9: 4 | B9: Обвязка радиаторов | C9: Комплект для радиаторов СТМ 1/2″ с 3 кронштейнами | D9: — | E9: 15 | F9: 265.6 | G9: =E9*F9 | H9: Комплект для радиатора 1/2″ (с 3 кронштейнами) ТМ | I9: — | J9: 15 | K9: 432 | L9: =J9*K9 | M9: =IF(F9=0,"",K9/F9-1) | N9: =IF(ABS(K9-F9)<0.005,"равно",IF(K9>F9,"МС дороже","КЛ дороже")) | O9: =L9-G9 | P9: Аналог | Q9: =J9-E9 | R9: СТМ vs ТМ
A10: 5 | B10: Обвязка радиаторов | C10: Клапан настроечный угловой 1/2″ с доп. уплотнением | D10: VT.019.NR.04 | E10: 15 | F10: 481.26 | G10: =E10*F10 | H10: Клапан настроечный VALTEC угловой 1/2″ с доп. уплотнением | I10: VT.019.NR.04 | J10: 15 | K10: 617 | L10: =J10*K10 | M10: =IF(F10=0,"",K10/F10-1) | N10: =IF(ABS(K10-F10)<0.005,"равно",IF(K10>F10,"МС дороже","КЛ дороже")) | O10: =L10-G10 | P10: Одинаковый артикул | Q10: =J10-E10
A11: 6 | B11: Обвязка радиаторов | C11: Клапан ручной угловой 1/2″ VALTEC компактный | D11: VT.007.LN.04 | E11: 15 | F11: 530.4 | G11: =E11*F11 | H11: Вентиль ручной ZEGOR угловой 1/2″ компактный | I11: QS-3461 | J11: 15 | K11: 476 | L11: =J11*K11 | M11: =IF(F11=0,"",K11/F11-1) | N11: =IF(ABS(K11-F11)<0.005,"равно",IF(K11>F11,"МС дороже","КЛ дороже")) | O11: =L11-G11 | P11: Аналог | Q11: =J11-E11 | R11: VALTEC vs ZEGOR. Здесь дешевле МС
A12: 7 | B12: Пресс-фитинги VALTEC | C12: Пресс соединение нар. рез. 16×1/2″ | D12: VTm.201.N.001604 | E12: 30 | F12: 180.18 | G12: =E12*F12 | H12: Соединитель пресс нар. рез. 16×1/2″ VALTEC | I12: VTm.201.N.001604 | J12: 30 | K12: 231 | L12: =J12*K12 | M12: =IF(F12=0,"",K12/F12-1) | N12: =IF(ABS(K12-F12)<0.005,"равно",IF(K12>F12,"МС дороже","КЛ дороже")) | O12: =L12-G12 | P12: Одинаковый артикул | Q12: =J12-E12
A13: 8 | B13: Пресс-фитинги VALTEC | C13: Пресс соединение нар. рез. 26×1″ | D13: VTm.201.N.002606 | E13: 10 | F13: 470.34 | G13: =E13*F13 | H13: Соединитель пресс нар. рез. 26×1″ VALTEC | I13: VTm.201.N.002606 | J13: 8 | K13: 603 | L13: =J13*K13 | M13: =IF(F13=0,"",K13/F13-1) | N13: =IF(ABS(K13-F13)<0.005,"равно",IF(K13>F13,"МС дороже","КЛ дороже")) | O13: =L13-G13 | P13: Одинаковый артикул | Q13: =J13-E13 | R13: В МС не хватает 2 шт
A14: 9 | B14: Пресс-фитинги VALTEC | C14: Пресс соединение вн. рез. 26×1″ | D14: VTm.202.N.002606 | E14: 4 | F14: 427.44 | G14: =E14*F14 | H14: Соединитель пресс вн. рез. 26×1″ VALTEC | I14: VTm.202.N.002606 | J14: 4 | K14: 548 | L14: =J14*K14 | M14: =IF(F14=0,"",K14/F14-1) | N14: =IF(ABS(K14-F14)<0.005,"равно",IF(K14>F14,"МС дороже","КЛ дороже")) | O14: =L14-G14 | P14: Одинаковый артикул | Q14: =J14-E14
A15: 10 | B15: Пресс-фитинги VALTEC | C15: Пресс соединение нар. рез. 26×3/4″ | D15: VTm.201.N.002605 | E15: 6 | F15: 443.82 | G15: =E15*F15 | H15: Соединитель пресс нар. рез. 26×3/4″ VALTEC | I15: VTm.201.N.002605 | J15: 5 | K15: 569 | L15: =J15*K15 | M15: =IF(F15=0,"",K15/F15-1) | N15: =IF(ABS(K15-F15)<0.005,"равно",IF(K15>F15,"МС дороже","КЛ дороже")) | O15: =L15-G15 | P15: Одинаковый артикул | Q15: =J15-E15 | R15: В МС не хватает 1 шт
A16: 11 | B16: Пресс-фитинги VALTEC | C16: Пресс соединение нар. рез. 20×3/4″ | D16: VTm.201.N.002005 | E16: 4 | F16: 265.98 | G16: =E16*F16 | H16: Соединитель пресс нар. рез. 20×3/4″ VALTEC | I16: VTm.201.N.002005 | J16: 4 | K16: 341 | L16: =J16*K16 | M16: =IF(F16=0,"",K16/F16-1) | N16: =IF(ABS(K16-F16)<0.005,"равно",IF(K16>F16,"МС дороже","КЛ дороже")) | O16: =L16-G16 | P16: Одинаковый артикул | Q16: =J16-E16
A17: 12 | B17: Пресс-фитинги VALTEC | C17: Пресс уголок 26×26 | D17: VTm.251.N.002626 | E17: 17 | F17: 599.04 | G17: =E17*F17 | H17: Угольник пресс 26 VALTEC | I17: VTm.251.N.002626 | J17: 17 | K17: 768 | L17: =J17*K17 | M17: =IF(F17=0,"",K17/F17-1) | N17: =IF(ABS(K17-F17)<0.005,"равно",IF(K17>F17,"МС дороже","КЛ дороже")) | O17: =L17-G17 | P17: Одинаковый артикул | Q17: =J17-E17
A18: 13 | B18: Пресс-фитинги VALTEC | C18: Пресс уголок 20×20 | D18: VTm.251.N.002020 | E18: 6 | F18: 378.3 | G18: =E18*F18 | H18: Угольник пресс 20 VALTEC | I18: VTm.251.N.002020 | J18: 6 | K18: 485 | L18: =J18*K18 | M18: =IF(F18=0,"",K18/F18-1) | N18: =IF(ABS(K18-F18)<0.005,"равно",IF(K18>F18,"МС дороже","КЛ дороже")) | O18: =L18-G18 | P18: Одинаковый артикул | Q18: =J18-E18
A19: 14 | B19: Пресс-фитинги VALTEC | C19: Пресс тройник 26×20×26 | D19: VTm.231.N.262026 | E19: 2 | F19: 802.62 | G19: =E19*F19 | H19: Тройник пресс 26×20×26 VALTEC | I19: VTm.231.N.262026 | J19: 2 | K19: 1029 | L19: =J19*K19 | M19: =IF(F19=0,"",K19/F19-1) | N19: =IF(ABS(K19-F19)<0.005,"равно",IF(K19>F19,"МС дороже","КЛ дороже")) | O19: =L19-G19 | P19: Одинаковый артикул | Q19: =J19-E19
A20: 15 | B20: Пресс-фитинги VALTEC | C20: Пресс тройник 20×16×20 | D20: VTm.231.N.201620 | E20: 4 | F20: 526.5 | G20: =E20*F20 | H20: Тройник пресс 20×16×20 VALTEC | I20: VTm.231.N.201620 | J20: 4 | K20: 675 | L20: =J20*K20 | M20: =IF(F20=0,"",K20/F20-1) | N20: =IF(ABS(K20-F20)<0.005,"равно",IF(K20>F20,"МС дороже","КЛ дороже")) | O20: =L20-G20 | P20: Одинаковый артикул | Q20: =J20-E20
A21: 16 | B21: Пресс-фитинги VALTEC | C21: Пресс тройник 26×26×26 | D21: VTm.231.N.262626 | E21: 1 | F21: 850.98 | G21: =E21*F21 | H21: Тройник пресс 26 VALTEC | I21: VTm.231.N.262626 | J21: 1 | K21: 1091 | L21: =J21*K21 | M21: =IF(F21=0,"",K21/F21-1) | N21: =IF(ABS(K21-F21)<0.005,"равно",IF(K21>F21,"МС дороже","КЛ дороже")) | O21: =L21-G21 | P21: Одинаковый артикул | Q21: =J21-E21
A22: 17 | B22: Трубы и изоляция | C22: Труба металлопластик Valtec 26×3 мм | D22: V2630 | E22: 50 | F22: 242.58 | G22: =E22*F22 | H22: Труба металлопластик 26 VALTEC (50 м) | I22: V2630.050 | J22: 50 | K22: 311 | L22: =J22*K22 | M22: =IF(F22=0,"",K22/F22-1) | N22: =IF(ABS(K22-F22)<0.005,"равно",IF(K22>F22,"МС дороже","КЛ дороже")) | O22: =L22-G22 | P22: Одинаковый товар | Q22: =J22-E22
A23: 18 | B23: Трубы и изоляция | C23: Труба металлопластик Valtec 20×2 мм | D23: V2020 | E23: 100 | F23: 133.38 | G23: =E23*F23 | H23: Труба металлопластик 20 VALTEC (100 м) | I23: V2020.100 | J23: 100 | K23: 171 | L23: =J23*K23 | M23: =IF(F23=0,"",K23/F23-1) | N23: =IF(ABS(K23-F23)<0.005,"равно",IF(K23>F23,"МС дороже","КЛ дороже")) | O23: =L23-G23 | P23: Одинаковый товар | Q23: =J23-E23
A24: 19 | B24: Трубы и изоляция | C24: Труба металлопластик Valtec 16×2 мм | D24: V1620.200 | E24: 1400 | F24: 100.62 | G24: =E24*F24 | H24: Труба металлопластик 16 VALTEC (200 м) | I24: V1620.200 | J24: 1400 | K24: 129 | L24: =J24*K24 | M24: =IF(F24=0,"",K24/F24-1) | N24: =IF(ABS(K24-F24)<0.005,"равно",IF(K24>F24,"МС дороже","КЛ дороже")) | O24: =L24-G24 | P24: Одинаковый артикул | Q24: =J24-E24 | R24: Самый большой вклад в разницу счетов
A25: 20 | B25: Трубы и изоляция | C25: Утеплитель цветной 18/4 красный | D25: VT.SP.R10R.1804 | E25: 220 | F25: 19.51 | G25: =E25*F25 | H25: Утеплитель трубный 18×4 VALTEC красный | I25: VT.SP.R10R.1804 | J25: 220 | K25: 23.5 | L25: =J25*K25 | M25: =IF(F25=0,"",K25/F25-1) | N25: =IF(ABS(K25-F25)<0.005,"равно",IF(K25>F25,"МС дороже","КЛ дороже")) | O25: =L25-G25 | P25: Одинаковый артикул | Q25: =J25-E25
A26: 21 | B26: Трубы и изоляция | C26: Утеплитель цветной 18/4 синий | D26: VT.SP.R10B.1804 | E26: 220 | F26: 19.51 | G26: =E26*F26 | H26: Утеплитель трубный 18×4 VALTEC синий | I26: VT.SP.R10B.1804 | J26: 220 | K26: 23.5 | L26: =J26*K26 | M26: =IF(F26=0,"",K26/F26-1) | N26: =IF(ABS(K26-F26)<0.005,"равно",IF(K26>F26,"МС дороже","КЛ дороже")) | O26: =L26-G26 | P26: Одинаковый товар | Q26: =J26-E26
A27: 22 | B27: Трубы и изоляция | C27: Втулка защитная 16 мм синяя VALTEC | D27: VT.VZT.16.B0 | E27: 26 | F27: 22.62 | G27: =E27*F27 | H27: Втулка защитная 16 мм синяя VALTEC | I27: VT.VZT.16.B0 | J27: 26 | K27: 27 | L27: =J27*K27 | M27: =IF(F27=0,"",K27/F27-1) | N27: =IF(ABS(K27-F27)<0.005,"равно",IF(K27>F27,"МС дороже","КЛ дороже")) | O27: =L27-G27 | P27: Одинаковый товар | Q27: =J27-E27
A28: 23 | B28: Трубы и изоляция | C28: Втулка защитная 16 мм красная VALTEC | D28: VT.VZT.16.R0 | E28: 26 | F28: 22.62 | G28: =E28*F28 | H28: Втулка защитная 16 мм красная VALTEC | I28: VT.VZT.16.R0 | J28: 26 | K28: 27 | L28: =J28*K28 | M28: =IF(F28=0,"",K28/F28-1) | N28: =IF(ABS(K28-F28)<0.005,"равно",IF(K28>F28,"МС дороже","КЛ дороже")) | O28: =L28-G28 | P28: Одинаковый товар | Q28: =J28-E28
A29: 24 | B29: Коллекторы тёплого пола | C29: Коллекторная группа ONDO нерж. 5 вых. с расходомерами | D29: — | E29: 1 | F29: 5976 | G29: =E29*F29 | H29: Коллекторная группа нерж. 1″ 5 вых. ТМ с расходомерами | I29: TOP1305 | J29: 1 | K29: 5784 | L29: =J29*K29 | M29: =IF(F29=0,"",K29/F29-1) | N29: =IF(ABS(K29-F29)<0.005,"равно",IF(K29>F29,"МС дороже","КЛ дороже")) | O29: =L29-G29 | P29: Аналог | Q29: =J29-E29 | R29: ONDO vs ТМ. Здесь дешевле МС
A30: 25 | B30: Коллекторы тёплого пола | C30: Коллекторная группа ONDO нерж. 8 вых. с расходомерами | D30: — | E30: 1 | F30: 7387 | G30: =E30*F30 | H30: Коллекторная группа нерж. 1″ 8 вых. ТМ с расходомерами | I30: TOP1308 | J30: 1 | K30: 9253 | L30: =J30*K30 | M30: =IF(F30=0,"",K30/F30-1) | N30: =IF(ABS(K30-F30)<0.005,"равно",IF(K30>F30,"МС дороже","КЛ дороже")) | O30: =L30-G30 | P30: Аналог | Q30: =J30-E30 | R30: ONDO vs ТМ
A31: 26 | B31: Коллекторы тёплого пола | C31: Евроконус для м/п трубы 16 VALTEC | D31: VT.4420.NVE.16 | E31: 26 | F31: 179.4 | G31: =E31*F31 | H31: Евроконус 16×3/4 для коллекторных групп VRT | I31: 524083 | J31: 26 | K31: 215 | L31: =J31*K31 | M31: =IF(F31=0,"",K31/F31-1) | N31: =IF(ABS(K31-F31)<0.005,"равно",IF(K31>F31,"МС дороже","КЛ дороже")) | O31: =L31-G31 | P31: Аналог | Q31: =J31-E31 | R31: VALTEC vs VRT
A32: 27 | B32: Смесители и насосы | C32: Насосно-смесительный узел VALTEC COMBI без насоса 180 мм | D32: VT.COMBI.0.180 | E32: 2 | F32: 27466.92 | G32: =E32*F32 | H32: Насосно-смесительный узел VALTEC COMBI без насоса 180 мм | I32: VT.COMBI.0.180 | J32: 2 | K32: 36623 | L32: =J32*K32 | M32: =IF(F32=0,"",K32/F32-1) | N32: =IF(ABS(K32-F32)<0.005,"равно",IF(K32>F32,"МС дороже","КЛ дороже")) | O32: =L32-G32 | P32: Одинаковый артикул | Q32: =J32-E32 | R32: Второй по вкладу в разницу счетов
A33: 28 | B33: Смесители и насосы | C33: Насос циркуляционный VALTEC RS 25/6-180 с гайками | D33: VRS.256.18.0 | E33: 4 | F33: 3330.6 | G33: =E33*F33 | H33: Насос циркуляционный VALTEC RS 25-60-180 с гайками | I33: VRS.256.18.0 | J33: 4 | K33: 4270 | L33: =J33*K33 | M33: =IF(F33=0,"",K33/F33-1) | N33: =IF(ABS(K33-F33)<0.005,"равно",IF(K33>F33,"МС дороже","КЛ дороже")) | O33: =L33-G33 | P33: Одинаковый артикул | Q33: =J33-E33
A34: 29 | B34: Смесители и насосы | C34: Гидрострелка Север-М2+1 | D34: — | E34: 1 | F34: 11553.6 | G34: =E34*F34 | H34: Разделитель гидравлический Дельта-У2+1 | I34: 1801009 | J34: 1 | K34: 11134 | L34: =J34*K34 | M34: =IF(F34=0,"",K34/F34-1) | N34: =IF(ABS(K34-F34)<0.005,"равно",IF(K34>F34,"МС дороже","КЛ дороже")) | O34: =L34-G34 | P34: Аналог | Q34: =J34-E34 | R34: Север vs Дельта. Здесь дешевле МС
A35: 30 | B35: Смесители и насосы | C35: Циркуляционный насос ГВС 130 мм VIEIR латунь | D35: VRT20-6-130 | E35: 1 | F35: 4565 | G35: =E35*F35 | H35: Насос циркуляционный Unipump LPA 20-60 B (ГВС, тёплый пол) | I35: 50260 | J35: 1 | K35: 11230 | L35: =J35*K35 | M35: =IF(F35=0,"",K35/F35-1) | N35: =IF(ABS(K35-F35)<0.005,"равно",IF(K35>F35,"МС дороже","КЛ дороже")) | O35: =L35-G35 | P35: Аналог | Q35: =J35-E35 | R35: Vieir 130 мм vs Unipump LPA. Разная монтажная длина и бренд
A36: 31 | B36: Краны и арматура | C36: Кран шаровый VALTEC BASE 1″ прямой со сгоном, бабочка | D36: VT.227S.N.06 | E36: 4 | F36: 1732.38 | G36: =E36*F36 | H36: Кран шаровый VALTEC BASE 1″ УГЛОВОЙ с полусгоном | I36: VT.228.N.06 | J36: 4 | K36: 2256 | L36: =J36*K36 | M36: =IF(F36=0,"",K36/F36-1) | N36: =IF(ABS(K36-F36)<0.005,"равно",IF(K36>F36,"МС дороже","КЛ дороже")) | O36: =L36-G36 | P36: Не эквивалент | Q36: =J36-E36 | R36: КРИТИЧНО: прямой кран vs угловой
A37: 32 | B37: Краны и арматура | C37: Кран шаровый VALTEC BASE 3/4″ со сгоном, бабочка | D37: VT.227S.N.05 | E37: 4 | F37: 793.26 | G37: =E37*F37 | H37: Кран шаровый VALTEC BASE 3/4″ г/ш с полусгоном, бабочка | I37: VT.227S.N.05 | J37: 4 | K37: 966 | L37: =J37*K37 | M37: =IF(F37=0,"",K37/F37-1) | N37: =IF(ABS(K37-F37)<0.005,"равно",IF(K37>F37,"МС дороже","КЛ дороже")) | O37: =L37-G37 | P37: Одинаковый артикул | Q37: =J37-E37
A38: 33 | B38: Краны и арматура | C38: Кран шаровый VALTEC с накидной гайкой 1″ вн.–нар. | D38: VT.260.N.0606 | E38: 4 | F38: 1001.52 | G38: =E38*F38 | H38: Кран шаровый VALTEC с накидной гайкой 1″ вн.–нар. | I38: VT.260.N.0606 | J38: 4 | K38: 1284 | L38: =J38*K38 | M38: =IF(F38=0,"",K38/F38-1) | N38: =IF(ABS(K38-F38)<0.005,"равно",IF(K38>F38,"МС дороже","КЛ дороже")) | O38: =L38-G38 | P38: Одинаковый артикул | Q38: =J38-E38
A39: 34 | B39: Краны и арматура | C39: Кран прямой 1/2″ с накидной гайкой VIEIR | D39: VERS50 | E39: 1 | F39: 410.85 | G39: =E39*F39 | H39: Кран шаровый с накидной гайкой 1/2″ г/г бабочка STI | I39: ТТ000016925 | J39: 1 | K39: 544 | L39: =J39*K39 | M39: =IF(F39=0,"",K39/F39-1) | N39: =IF(ABS(K39-F39)<0.005,"равно",IF(K39>F39,"МС дороже","КЛ дороже")) | O39: =L39-G39 | P39: Аналог | Q39: =J39-E39 | R39: VIEIR vs STI
A40: 35 | B40: Краны и арматура | C40: Кран прямой 3/4″ с накидной гайкой VIEIR | D40: VERS51 | E40: 4 | F40: 730.4 | G40: =E40*F40 | H40: Кран шаровый с накидной гайкой 3/4″ г/г бабочка STI | I40: ТТ000016926 | J40: 4 | K40: 771 | L40: =J40*K40 | M40: =IF(F40=0,"",K40/F40-1) | N40: =IF(ABS(K40-F40)<0.005,"равно",IF(K40>F40,"МС дороже","КЛ дороже")) | O40: =L40-G40 | P40: Аналог | Q40: =J40-E40 | R40: VIEIR vs STI
A41: 36 | B41: Краны и арматура | C41: Воздухоотводчик автоматический 1/2″ VALTEC | D41: VT.502.NH.04 | E41: 1 | F41: 573.3 | G41: =E41*F41 | H41: Воздухоотводчик автоматический 1/2″ VALTEC | I41: VT.502.NH.04 | J41: 1 | K41: 735 | L41: =J41*K41 | M41: =IF(F41=0,"",K41/F41-1) | N41: =IF(ABS(K41-F41)<0.005,"равно",IF(K41>F41,"МС дороже","КЛ дороже")) | O41: =L41-G41 | P41: Одинаковый артикул | Q41: =J41-E41
...

Sheet Замены и аналоги
A1: Замены и аналоги · один функционал, разные бренд / серия / модель
A2: Эти позиции есть в обоих документах, но это не один и тот же артикул. Цены сравнивать можно только как ориентир.
A4: № | B4: Группа | C4: КЛ-1864 | D4: Артикул КЛ | E4: Кол-во | F4: Цена КЛ | G4: МС | H4: Артикул МС | I4: Кол-во | J4: Цена МС | K4: Δ цена | L4: Δ сумма, ₽ | M4: Суть замены
A5: 1 | B5: Радиаторы | C5: Радиатор алюм. Royal Thermo Revolution 500, 8 секц. | D5: — | E5: 6 | F5: 7333.6 | G5: Радиатор алюм. Royal Thermo MONOBLOCK A 500×80, 8 секц. | H5: 542451 | I5: 6 | J5: 8266 | K5: 0.12714083 | L5: 5594.4 | M5: Аналог. Другая серия: Revolution vs MONOBLOCK A
A6: 2 | B6: Радиаторы | C6: Радиатор алюм. Royal Thermo Revolution 500, 6 секц. | D6: — | E6: 6 | F6: 5500.2 | G6: Радиатор алюм. Royal Thermo MONOBLOCK A 500×80, 10 секц. | H6: 542452 | I6: 6 | J6: 10856 | K6: 0.97374641 | L6: 32134.8 | M6: Не эквивалент. КРИТИЧНО: 6 секций vs 10 секций + другая серия
A7: 3 | B7: Радиаторы | C7: Радиатор алюм. Royal Thermo Revolution 500, 12 секц. | D7: — | E7: 3 | F7: 11000.4 | G7: Радиатор алюм. Royal Thermo MONOBLOCK A 500×80, 12 секц. | H7: 542453 | I7: 3 | J7: 12400 | K7: 0.12723174 | L7: 4198.8 | M7: Аналог. Другая серия: Revolution vs MONOBLOCK A
A8: 4 | B8: Обвязка радиаторов | C8: Комплект для радиаторов СТМ 1/2″ с 3 кронштейнами | D8: — | E8: 15 | F8: 265.6 | G8: Комплект для радиатора 1/2″ (с 3 кронштейнами) ТМ | H8: — | I8: 15 | J8: 432 | K8: 0.62650602 | L8: 2496 | M8: Аналог. СТМ vs ТМ
A9: 5 | B9: Обвязка радиаторов | C9: Клапан ручной угловой 1/2″ VALTEC компактный | D9: VT.007.LN.04 | E9: 15 | F9: 530.4 | G9: Вентиль ручной ZEGOR угловой 1/2″ компактный | H9: QS-3461 | I9: 15 | J9: 476 | K9: -0.1025641 | L9: -816 | M9: Аналог. VALTEC vs ZEGOR. Здесь дешевле МС
A10: 6 | B10: Коллекторы тёплого пола | C10: Коллекторная группа ONDO нерж. 5 вых. с расходомерами | D10: — | E10: 1 | F10: 5976 | G10: Коллекторная группа нерж. 1″ 5 вых. ТМ с расходомерами | H10: TOP1305 | I10: 1 | J10: 5784 | K10: -0.032128514 | L10: -192 | M10: Аналог. ONDO vs ТМ. Здесь дешевле МС
A11: 7 | B11: Коллекторы тёплого пола | C11: Коллекторная группа ONDO нерж. 8 вых. с расходомерами | D11: — | E11: 1 | F11: 7387 | G11: Коллекторная группа нерж. 1″ 8 вых. ТМ с расходомерами | H11: TOP1308 | I11: 1 | J11: 9253 | K11: 0.25260593 | L11: 1866 | M11: Аналог. ONDO vs ТМ
A12: 8 | B12: Коллекторы тёплого пола | C12: Евроконус для м/п трубы 16 VALTEC | D12: VT.4420.NVE.16 | E12: 26 | F12: 179.4 | G12: Евроконус 16×3/4 для коллекторных групп VRT | H12: 524083 | I12: 26 | J12: 215 | K12: 0.19843924 | L12: 925.6 | M12: Аналог. VALTEC vs VRT
A13: 9 | B13: Смесители и насосы | C13: Гидрострелка Север-М2+1 | D13: — | E13: 1 | F13: 11553.6 | G13: Разделитель гидравлический Дельта-У2+1 | H13: 1801009 | I13: 1 | J13: 11134 | K13: -0.036317685 | L13: -419.6 | M13: Аналог. Север vs Дельта. Здесь дешевле МС
A14: 10 | B14: Смесители и насосы | C14: Циркуляционный насос ГВС 130 мм VIEIR латунь | D14: VRT20-6-130 | E14: 1 | F14: 4565 | G14: Насос циркуляционный Unipump LPA 20-60 B (ГВС, тёплый пол) | H14: 50260 | I14: 1 | J14: 11230 | K14: 1.4600219 | L14: 6665 | M14: Аналог. Vieir 130 мм vs Unipump LPA. Разная монтажная длина и бренд
A15: 11 | B15: Краны и арматура | C15: Кран шаровый VALTEC BASE 1″ прямой со сгоном, бабочка | D15: VT.227S.N.06 | E15: 4 | F15: 1732.38 | G15: Кран шаровый VALTEC BASE 1″ УГЛОВОЙ с полусгоном | H15: VT.228.N.06 | I15: 4 | J15: 2256 | K15: 0.3022547 | L15: 2094.48 | M15: Не эквивалент. КРИТИЧНО: прямой кран vs угловой
A16: 12 | B16: Краны и арматура | C16: Кран прямой 1/2″ с накидной гайкой VIEIR | D16: VERS50 | E16: 1 | F16: 410.85 | G16: Кран шаровый с накидной гайкой 1/2″ г/г бабочка STI | H16: ТТ000016925 | I16: 1 | J16: 544 | K16: 0.32408422 | L16: 133.15 | M16: Аналог. VIEIR vs STI
... A21: 17 | B21: Краны и арматура | C21: Переход вн. 1¼″×1″ VALTEC | D21: VTr.592.N.0706 | E21: 2 | F21: 404.82 | G21: Переходник 1¼″ вн. × 1″ нар. лат. LEXLINE | H21: 512231 | I21: 2 | J21: 413 | K21: 0.020206512 | L21: 16.36 | M21: Аналог. VALTEC vs LEXLINE
A22: Итого замен и не-эквивалентов: 17 позиций | L22: =SUM(L5:L21)
A24: Красные строки «Не эквивалент» — это уже не замена «один в один»: перед оплатой нужно подтвердить, что 10-секционный радиатор и угловой кран действительно нужны.

Sheet Не хватает и несовпадения
B2: Не хватает и несовпадения
B3: Полностью отсутствующих позиций нет. Ниже — разница в количестве и случаи, когда под одним номером строки стоят разные товары.
B5: 1. Количество: в МС меньше, чем в КЛ-1864
B6: Позиция | C6: Артикул | D6: Кол-во КЛ | E6: Кол-во МС | F6: Не хватает | G6: Цена КЛ, ₽ | H6: Сумма нехватки, ₽ | I6: Комментарий
B7: Пресс соединение нар. 26×1″ | C7: VTm.201.N.002606 | D7: 10 | E7: 8 | F7: 2 | G7: 470.34 | H7: 940.68 | I7: В КЛ две строки (4+6), в МС три строки (4+2+2). Итого в МС на 2 шт меньше.
B8: Пресс соединение нар. 26×3/4″ | C8: VTm.201.N.002605 | D8: 6 | E8: 5 | F8: 1 | G8: 443.82 | H8: 443.82 | I8: В КЛ одна строка 6 шт, в МС две строки (3+2). Итого в МС на 1 шт меньше.
B9: Итого не хватает в МС | H9: =H7+H8
B11: 2. Разный товар под «той же» позицией спецификации
B12: Что в КЛ-1864 | C12: Что в МС | D12: Кол-во | E12: Цена КЛ | F12: Цена МС | G12: Δ цены | H12: Δ суммы | I12: Почему это проблема
B13: RT Revolution 500, 6 секций | C13: RT MONOBLOCK A 500, 10 секций | D13: 6 | E13: 5500.2 | F13: 10856 | G13: 0.97374641 | H13: 32134.8 | I13: Другая серия и на 4 секции больше. Теплоотдача, цена и габарит несопоставимы. МС дороже на 97% (+32 135 ₽).
B14: Кран VALTEC VT.227S.N.06 прямой 1″ со сгоном | C14: Кран VALTEC VT.228.N.06 угловой 1″ с полусгоном | D14: 4 | E14: 1732.38 | F14: 2256 | G14: 0.3022547 | H14: 2094.48 | I14: Прямой кран нельзя без проекта менять на угловой: другая геометрия обвязки котла/коллектора. МС дороже на 30%.
B16: 3. Чего нет «лишнего»
B17: В МС нет позиций, которых не было бы в КЛ-1864 по смыслу. Оба документа закрывают один комплект: радиаторы, обвязка, трубы VALTEC 16/20/26, изоляция, коллекторы 5+8, два смесительных узла COMBI, 4 насоса RS 25/6, гидрострелка, насос ГВС, краны и фитинги. Расхождение — в брендах аналогов, в двух критичных заменах выше и в трёх пресс-фитингах.
B20: 4. Контроль количества по всем 41 позициям
B21: Формула с листа «Сравнение позиций»: если Δ кол-во ≠ 0, строка попадает в список. Сейчас таких строк две (см. блок 1).
B23: Позиций с разным количеством | C23: =COUNTIF('Сравнение позиций'!Q6:Q46,"<>0") | D23: См. блок 1 на этом листе
B24: Позиций-аналогов | C24: =COUNTIF('Сравнение позиций'!P6:P46,"Аналог") | D24: См. лист «Замены и аналоги»
B25: Позиций «не эквивалент» | C25: =COUNTIF('Сравнение позиций'!P6:P46,"Не эквивалент") | D25: Радиатор 6→10 секц. и кран прямой→угловой
B26: Позиций один в один | C26: =COUNTIF('Сравнение позиций'!P6:P46,"Одинаковый артикул")+COUNTIF('Сравнение позиций'!P6:P46,"Одинаковый товар") | D26: Можно сравнивать цены напрямую, без оговорок по модели
